<?xml version="1.0" ?>
<robot name="colmena" xmlns:xacro="http://www.ros.org/wiki/xacro">

  <xacro:include filename="$(find colmena_description)/urdf/materials.xacro" />

  <link name="base_link"/>

  <link name="chassis">
    <inertial>
      <mass value="0.026732"/>
      <origin xyz="0 0 0" rpy="0.0 0.0 0.0"/>
      <inertia 
        ixx="0.00002316" 
        ixy="0.0" 
        ixz="0.0" 
        iyy="0.00003237" 
        iyz="0.0" 
        izz="0.000054989"/>
    </inertial>
    <visual>
      <origin xyz="0 0 0" rpy="0 0 0"/>
      <geometry>
        <mesh filename="file://$(find colmena_description)/meshes/chassis.stl" scale="0.001 0.001 0.001"/>
      </geometry>
      <material name="silver"/>
    </visual>
    <collision>
      <origin xyz="0 0 0" rpy="0 0 0"/>
      <geometry>
        <mesh filename="file://$(find colmena_description)/meshes/chassis.stl" scale="0.001 0.001 0.001"/>
      </geometry>
    </collision>
  </link>

  <link name="right_wheel">
    <inertial>
      <mass value="0.00299"/>
      <origin xyz="0 0 0" rpy="0.0 0.0 0.0"/>
      <inertia 
        ixx="0.000000632" 
        ixy="0.0" 
        ixz="0.0" 
        iyy="0.000001225" 
        iyz="0.0" 
        izz="0.000000632"/>
    </inertial>
    <visual>
      <origin xyz="0 0 0" rpy="0 0 0"/>
      <geometry>
        <mesh filename="file://$(find colmena_description)/meshes/right_wheel.stl" scale="0.001 0.001 0.001"/>
      </geometry>
      <material name="black"/>
    </visual>
    <collision>
      <origin xyz="0 0 0" rpy="0 0 0"/>
      <geometry>
        <mesh filename="file://$(find colmena_description)/meshes/right_wheel.stl" scale="0.001 0.001 0.001"/>
      </geometry>
    </collision>
  </link>

  <link name="left_wheel">
    <inertial>
      <mass value="0.00299"/>
      <origin xyz="0 0 0" rpy="0.0 0.0 0.0"/>
      <inertia 
        ixx="0.000000632" 
        ixy="0.0" 
        ixz="0.0" 
        iyy="0.000001225" 
        iyz="0.0" 
        izz="0.000000632"/>
    </inertial>
    <visual>
      <origin xyz="0 0 0" rpy="0 0 0"/>
      <geometry>
        <mesh filename="file://$(find colmena_description)/meshes/left_wheel.stl" scale="0.001 0.001 0.001"/>
      </geometry>
      <material name="black"/>
    </visual>
    <collision>
      <origin xyz="0 0 0" rpy="0 0 0"/>
      <geometry>
        <mesh filename="file://$(find colmena_description)/meshes/left_wheel.stl" scale="0.001 0.001 0.001"/>
      </geometry>
    </collision>
  </link>

  <joint name="ch_to_bl_joint" type="fixed">
    <parent link="base_link"/>
    <child link="chassis"/>
    <origin xyz="-0.003286 0.0 0.00045"/>
  </joint>

  <joint name="rw_to_bl_joint" type="continuous">
    <parent link="base_link"/>
    <child link="right_wheel"/>
    <origin xyz="0.0 -0.041521 0.0"/>
    <axis xyz="0 1 0"/>
  </joint>

  <joint name="lw_to_bl_joint" type="continuous">
    <parent link="base_link"/>
    <child link="left_wheel"/>
    <origin xyz="0.0 0.041521 0.0"/>
    <axis xyz="0 1 0"/>
  </joint>

</robot>